Workbook

Sheet Deckblatt
B2: Hitachi Rail
B3: Interne Abnahmeprüfung (FFT) · ITC
B5: Prüfprotokoll Fahrstraßenoberfläche
B6: TIP S2 – Software Fahrstraßenoberfläche und Prüfanleitung PT1
B7: ESTW L90 · Domestic · DB InfraGO
B9: Projektdaten (gelbe Felder ausfüllen)
B10: Projektbezeichnung / PSP
B11: Stellwerk (UZ / ESTW-Z, Ril100)
B12: Bauzustand / AZ-Nr.
B13: Systemversionen (LBS, MEM, SM, EAM, AzLM)
B14: PT1-Stand laut PBL
B15: Neuanlage / Bauzustand (Differenz)
... B19: Herkunft der Fragen
B20: TIP S2 | C20: Frage aus dem TIP S2 – Software Fahrstraßenoberfläche. Zeile hellorange. Formal verbindlich; Ergebnis 1:1 ins TIP übertragen.
B21: PA | C21: Prüfanleitung: Einzelschritt (PT1-Tabelle, Prüfdokument, Simulation), mit dem eine TIP-Frage nachgewiesen wird. Aus der Schulungsunterlage, teils auf Basis historischer Arbeitsnotizen – vor Nutzung mit aktuellem Stand abgleichen.
B23: Bewertung
B24: i. O. – in Ordnung | C24: TIP: Ja | D24: Entspricht der Vorgabe (PT1, Prüfdokument, Planung).
B25: n. i. O. – nicht in Ordnung | C25: TIP: Nein | D25: Abweichung im Prüfbuch erfassen, Prüfbuch-Nr. in „Bemerkung“.
B26: n. z. – nicht zutreffend | C26: TIP: als n. z. kennzeichnen | D26: Sachverhalt kommt nicht vor; kurz begründen.
B28: Bedienung der Excel-Datei
B29: • Je Zeile genau ein Kästchen anhaken. „Status“ zeigt offen / erledigt / n. i. O. / mehrfach!.
B30: • Eine TIP-Frage erst mit i. O. bewerten, wenn alle zugehörigen PA-Schritte i. O. oder n. z. sind.
B31: • Spalte „Bezug (Link)“: TIP-Frage → erster zugehöriger PA-Schritt („+n“ = weitere); PA-Schritt → TIP-Frage. ↑ = weiter oben, ↓ = weiter unten.
B32: • Filter in Spalte „Herkunft“: nur TIP- oder nur PA-Zeilen anzeigen.
B33: • Nachweis der PT1-Prüfung bleibt das Abhaken im PT1 (TIP-Manteldokument, Anhang A.1).
B34: • Kästchen = Zellkontrollkästchen (Microsoft 365). Ältere Excel-Versionen zeigen WAHR/FALSCH; Wert dann per Eingabe ändern.

Sheet Prüfprotokoll
A1: Prüfprotokoll Fahrstraßenoberfläche – TIP S2 – Software Fahrstraßenoberfläche und Prüfanleitung
A2: ESTW L90 · DB InfraGO · Prüfgrundlagen: TIP S2 (Template-Ausg. 01), Schulungsunterlage Softwareprüfung ESTW L90 (Phase 5) · Projektdaten und Anleitung: Blatt „Deckblatt“
A4: Nr. | B4: Herkunft | C4: TIP-Nr. / PA | D4: Prüffrage | E4: Bezug (Link) | F4: i. O. | G4: n. i. O. | H4: n. z. | I4: Status | J4: Bemerkung / Prüfbuch-Nr.
A5: 2 Zugstraßen
A6: TIP S2 – Zugstraßen
A7: 1 | B7: TIP S2 | C7: Nr. 1 | D7: Jede Zugstraße ist mindestens einmal einzustellen, das Startsignal mit HAGT in Halt zu stellen und die Zugstraße mit FHA aufzulösen. (Einstellen mit „S,“ in gesperrte Gleise ist nicht zusätzlich erforderlich.) | F7: FALSE | G7: FALSE | H7: FALSE | I7: =IF(COUNTIF(F7:H7,TRUE)=0,"offen",IF(COUNTIF(F7:H7,TRUE)>1,"mehrfach!",IF(G7=TRUE,"n. i. O.","erledigt"))) -> offen
A8: 2 | B8: TIP S2 | C8: Nr. 2 | D8: Stimmt der Zugstraßenbefehl mit der Vorgabe in der Zugstraßentabelle überein? | E8: ↓ PA 4 | F8: FALSE | G8: FALSE | H8: FALSE | I8: =IF(COUNTIF(F8:H8,TRUE)=0,"offen",IF(COUNTIF(F8:H8,TRUE)>1,"mehrfach!",IF(G8=TRUE,"n. i. O.","erledigt"))) -> offen
A9: 3 | B9: TIP S2 | C9: Nr. 3 | D9: Sind Zugstraßen in nicht überspannte Bereiche mit „F,“ projektiert? | F9: FALSE | G9: FALSE | H9: FALSE | I9: =IF(COUNTIF(F9:H9,TRUE)=0,"offen",IF(COUNTIF(F9:H9,TRUE)>1,"mehrfach!",IF(G9=TRUE,"n. i. O.","erledigt"))) -> offen
A10: 4 | B10: TIP S2 | C10: Nr. 4 | D10: Werden alle nach Signaltabelle 2 geforderten Signalbegriffe kommandiert, und werden alle Zs-Signale, die nicht angeschaltet werden, dunkel kommandiert? | E10: ↓ PA 1 (+1) | F10: FALSE | G10: FALSE | H10: FALSE | I10: =IF(COUNTIF(F10:H10,TRUE)=0,"offen",IF(COUNTIF(F10:H10,TRUE)>1,"mehrfach!",IF(G10=TRUE,"n. i. O.","erledigt"))) -> offen
A11: 5 | B11: TIP S2 | C11: Nr. 5 | D11: Ist der Haltfall korrekt projektiert? | E11: ↓ PA 3 | F11: FALSE | G11: FALSE | H11: FALSE | I11: =IF(COUNTIF(F11:H11,TRUE)=0,"offen",IF(COUNTIF(F11:H11,TRUE)>1,"mehrfach!",IF(G11=TRUE,"n. i. O.","erledigt"))) -> offen
A12: 6 | B12: TIP S2 | C12: Nr. 6 | D12: Ist der Flankenschutz nach Flankenschutztabelle projektiert? | E12: ↓ PA 11 (+2) | F12: FALSE | G12: FALSE | H12: FALSE | I12: =IF(COUNTIF(F12:H12,TRUE)=0,"offen",IF(COUNTIF(F12:H12,TRUE)>1,"mehrfach!",IF(G12=TRUE,"n. i. O.","erledigt"))) -> offen
A13: 7 | B13: TIP S2 | C13: Nr. 7 | D13: Ist der D-Weg nach D-Weg-Tabelle projektiert, und wird er mit Belegung des geforderten Zielgleisabschnitts automatisch aufgelöst? | E13: ↓ PA 8 (+2) | F13: FALSE | G13: FALSE | H13: FALSE | I13: =IF(COUNTIF(F13:H13,TRUE)=0,"offen",IF(COUNTIF(F13:H13,TRUE)>1,"mehrfach!",IF(G13=TRUE,"n. i. O.","erledigt"))) -> offen
A14: 8 | B14: TIP S2 | C14: Nr. 8 | D14: Ist die Aufwertung bei Durchfahrten, soweit gefordert, projektiert? | E14: ↓ PA 2 (+1) | F14: FALSE | G14: FALSE | H14: FALSE | I14: =IF(COUNTIF(F14:H14,TRUE)=0,"offen",IF(COUNTIF(F14:H14,TRUE)>1,"mehrfach!",IF(G14=TRUE,"n. i. O.","erledigt"))) -> offen
A15: 9 | B15: TIP S2 | C15: Nr. 9 | D15: Sind die Annäherungsverschlüsse nach Zugstraßentabelle projektiert? (Ohne Angaben in der Planungsunterlage gilt gemäß Ril 818.8048 mindestens 150 m vor dem Vorsignal.) | E15: ↓ PA 5 (+2) | F15: FALSE | G15: FALSE | H15: FALSE | I15: =IF(COUNTIF(F15:H15,TRUE)=0,"offen",IF(COUNTIF(F15:H15,TRUE)>1,"mehrfach!",IF(G15=TRUE,"n. i. O.","erledigt"))) -> offen
A16: 10 | B16: TIP S2 | C16: Nr. 10 | D16: Ist bei mehreren Blockabschnitten vor Einfahrsignalen der Annäherungsverschluss auch ohne Fahrstraße wirksam (falls das Vorsignal dabei im vorletzten Blockabschnitt angeordnet ist)? | F16: FALSE | G16: FALSE | H16: FALSE | I16: =IF(COUNTIF(F16:H16,TRUE)=0,"offen",IF(COUNTIF(F16:H16,TRUE)>1,"mehrfach!",IF(G16=TRUE,"n. i. O.","erledigt"))) -> offen
A17: Prüfanleitung – Signaltabelle Teil 2
A18: 11 | B18: PA | C18: PA 1 | D18: Signaltabelle 2: Wurden je Fahrstraße alle Signale (inkl. Vor- und Geschwindigkeitsanzeiger) in SIMBA aufgeschaltet, die Fahrstraße eingestellt und die Signalbegriffe mit Signaltabelle 2 verglichen und abgehakt? | E18: ↑ S2 Nr. 4 | F18: FALSE | G18: FALSE | H18: FALSE | I18: =IF(COUNTIF(F18:H18,TRUE)=0,"offen",IF(COUNTIF(F18:H18,TRUE)>1,"mehrfach!",IF(G18=TRUE,"n. i. O.","erledigt"))) -> offen
A19: 12 | B19: PA | C19: PA 2 | D19: Signaltabelle 2: Wurden Unstimmigkeiten in der rückgelesenen Fahrstraßenliste (<Stw>R<n>.FBL) bzw. ELX geklärt (FS-Nummer → Aufwertung ja/nein, Sonderaktionsblock BÜ)? | E19: ↑ S2 Nr. 4, 8 | F19: FALSE | G19: FALSE | H19: FALSE | I19: =IF(COUNTIF(F19:H19,TRUE)=0,"offen",IF(COUNTIF(F19:H19,TRUE)>1,"mehrfach!",IF(G19=TRUE,"n. i. O.","erledigt"))) -> offen
A20: Prüfanleitung – Haltfall und Annäherungsverschluss
A21: 13 | B21: PA | C21: PA 3 | D21: Zugstraßentabelle: Haltfall (1× je Signal): Abschnitt vor dem Signal, 1. und 2. Abschnitt nach dem Signal nacheinander belegt – fällt das Signal an der geplanten Stelle in Halt? Abschnitte in derselben Reihenfolge wieder freigemeldet? | E21: ↑ S2 Nr. 5 | F21: FALSE | G21: FALSE | H21: FALSE | I21: =IF(COUNTIF(F21:H21,TRUE)=0,"offen",IF(COUNTIF(F21:H21,TRUE)>1,"mehrfach!",IF(G21=TRUE,"n. i. O.","erledigt"))) -> offen
A22: 14 | B22: PA | C22: PA 4 | D22: Zugstraßentabelle: Wurden die ZL-Begriffe über die Menüführung geprüft? | E22: ↑ S2 Nr. 2 | F22: FALSE | G22: FALSE | H22: FALSE | I22: =IF(COUNTIF(F22:H22,TRUE)=0,"offen",IF(COUNTIF(F22:H22,TRUE)>1,"mehrfach!",IF(G22=TRUE,"n. i. O.","erledigt"))) -> offen
A23: 15 | B23: PA | C23: PA 5 | D23: Zugstraßentabelle: Annäherungsverschluss: Zug vor dem Annäherungsabschnitt angehalten, Signal auf Halt – ist die Rücknahme ohne FHAE möglich? | E23: ↑ S2 Nr. 9 | F23: FALSE | G23: FALSE | H23: FALSE | I23: =IF(COUNTIF(F23:H23,TRUE)=0,"offen",IF(COUNTIF(F23:H23,TRUE)>1,"mehrfach!",IF(G23=TRUE,"n. i. O.","erledigt"))) -> offen
A24: 16 | B24: PA | C24: PA 6 | D24: Zugstraßentabelle: Annäherungsverschluss: Zug im Annäherungsabschnitt angehalten, Signal auf Halt – ist die Rücknahme nur mit FHAE möglich? (nur Abschnitte mit FHAE-Bedienung, nicht bei Blocksignalen) | E24: ↑ S2 Nr. 9 | F24: FALSE | G24: FALSE | H24: FALSE | I24: =IF(COUNTIF(F24:H24,TRUE)=0,"offen",IF(COUNTIF(F24:H24,TRUE)>1,"mehrfach!",IF(G24=TRUE,"n. i. O.","erledigt"))) -> offen
A25: 17 | B25: PA | C25: PA 7 | D25: Zugstraßentabelle: Wurde das Formblatt Annäherung/Anrücken (<Stw>IF.FBL) geprüft (0 = Bit gelöscht, T = transportiert, X = gesetzt) – inkl. Kommentare – und die Annäherungsverschlüsse in der Zugstraßentabelle vermerkt? | E25: ↑ S2 Nr. 9 | F25: FALSE | G25: FALSE | H25: FALSE | I25: =IF(COUNTIF(F25:H25,TRUE)=0,"offen",IF(COUNTIF(F25:H25,TRUE)>1,"mehrfach!",IF(G25=TRUE,"n. i. O.","erledigt"))) -> offen
A26: Prüfanleitung – D-Weg-Tabelle
A27: 18 | B27: PA | C27: PA 8 | D27: D-Weg-Tabelle: Wurde die Reichweite jedes D-Wegs durch Einstellen der Fahrstraße geprüft und im PT1 abgehakt? | E27: ↑ S2 Nr. 7 | F27: FALSE | G27: FALSE | H27: FALSE | I27: =IF(COUNTIF(F27:H27,TRUE)=0,"offen",IF(COUNTIF(F27:H27,TRUE)>1,"mehrfach!",IF(G27=TRUE,"n. i. O.","erledigt"))) -> offen
A28: 19 | B28: PA | C28: PA 9 | D28: D-Weg-Tabelle: D-Weg-Expansion (Zugstraßentabelle): Wird bei zulässiger Expansion mit Einstellen der Weiterfahrt der kurze D-Weg auf den längsten D-Weg expandiert und die Signalisierung entsprechend aufgewertet? | E28: ↑ S2 Nr. 7, 8 | F28: FALSE | G28: FALSE | H28: FALSE | I28: =IF(COUNTIF(F28:H28,TRUE)=0,"offen",IF(COUNTIF(F28:H28,TRUE)>1,"mehrfach!",IF(G28=TRUE,"n. i. O.","erledigt"))) -> offen
A29: 20 | B29: PA | C29: PA 10 | D29: D-Weg-Tabelle: Ist bei Startsignalen mit abgestufter Geschwindigkeitssignalisierung an allen Zielsignalen keine D-Weg-Expansion projektiert? | E29: ↑ S2 Nr. 7 | F29: FALSE | G29: FALSE | H29: FALSE | I29: =IF(COUNTIF(F29:H29,TRUE)=0,"offen",IF(COUNTIF(F29:H29,TRUE)>1,"mehrfach!",IF(G29=TRUE,"n. i. O.","erledigt"))) -> offen
A30: Prüfanleitung – Flankenschutztabelle (Fahrstraße)
A31: 21 | B31: PA | C31: PA 11 | D31: Flankenschutztabelle: Bei eingestellter Fahrstraße die flankenschutzgebende Weiche gestört: Fällt das Signal auf Halt und wechselt die Bezeichnung der geschützten Weiche von grün nach gelb? | E31: ↑ S2 Nr. 6 | F31: FALSE | G31: FALSE | H31: FALSE | I31: =IF(COUNTIF(F31:H31,TRUE)=0,"offen",IF(COUNTIF(F31:H31,TRUE)>1,"mehrfach!",IF(G31=TRUE,"n. i. O.","erledigt"))) -> offen
A32: 22 | B32: PA | C32: PA 12 | D32: Flankenschutztabelle: Gibt ein Signal Flankenschutz: Signal gestört („dunkel“) – verliert die geschützte Weiche den Flankenschutz? | E32: ↑ S2 Nr. 6 | F32: FALSE | G32: FALSE | H32: FALSE | I32: =IF(COUNTIF(F32:H32,TRUE)=0,"offen",IF(COUNTIF(F32:H32,TRUE)>1,"mehrfach!",IF(G32=TRUE,"n. i. O.","erledigt"))) -> offen
A33: 23 | B33: PA | C33: PA 13 | D33: Flankenschutztabelle: Führt die Belegung des überwachten Schutzraums zum Wechsel der Weichenbezeichnung von grün nach gelb? | E33: ↑ S2 Nr. 6 | F33: FALSE | G33: FALSE | H33: FALSE | I33: =IF(COUNTIF(F33:H33,TRUE)=0,"offen",IF(COUNTIF(F33:H33,TRUE)>1,"mehrfach!",IF(G33=TRUE,"n. i. O.","erledigt"))) -> offen
A34: 3 Überdrückte Zugstraßen
A35: TIP S2 – Überdrückte Zugstraßen
A36: 24 | B36: TIP S2 | C36: Nr. 11 | D36: Sind die nach Planungsunterlage geforderten überdrückten Zugstraßen projektiert, und sind sie aus den richtigen Einzelfahrstraßen zusammengesetzt? | F36: FALSE | G36: FALSE | H36: FALSE | I36: =IF(COUNTIF(F36:H36,TRUE)=0,"offen",IF(COUNTIF(F36:H36,TRUE)>1,"mehrfach!",IF(G36=TRUE,"n. i. O.","erledigt"))) -> offen
A37: 25 | B37: TIP S2 | C37: Nr. 12 | D37: Jede überdrückte Zugstraße ist einmal einzustellen und danach die Ausfahrt aufzulösen. Wurde die Einfahrt mit dem längsten möglichen D-Weg projektiert? | E37: ↓ PA 14 | F37: FALSE | G37: FALSE | H37: FALSE | I37: =IF(COUNTIF(F37:H37,TRUE)=0,"offen",IF(COUNTIF(F37:H37,TRUE)>1,"mehrfach!",IF(G37=TRUE,"n. i. O.","erledigt"))) -> offen
A38: Prüfanleitung – Tabelle der aneinandergereihten Zugstraßen
A39: 26 | B39: PA | C39: PA 14 | D39: Aneinandergereihte Zugstraßen: Durchfahrt eingestellt, Ausfahrsignal auf Halt, Ausfahrt einzeln aufgelöst: Bleibt für die Einfahrt der längste D-Weg (D1) bestehen? | E39: ↑ S2 Nr. 12 | F39: FALSE | G39: FALSE | H39: FALSE | I39: =IF(COUNTIF(F39:H39,TRUE)=0,"offen",IF(COUNTIF(F39:H39,TRUE)>1,"mehrfach!",IF(G39=TRUE,"n. i. O.","erledigt"))) -> offen
A40: 4 Rangierstraßen
A41: TIP S2 – Rangierstraßen
...

Sheet Ergebnis
B2: Ergebnis – Prüfprotokoll Fahrstraßenoberfläche
B4: Abschnitt | C4: TIP S2 | D4: PA | E4: i. O. | F4: n. i. O. | G4: n. z. | H4: offen | I4: mehrfach
B5: 2 Zugstraßen | C5: =COUNTIF(Prüfprotokoll!B6:B33,"TIP S2") -> 0 | D5: =COUNTIF(Prüfprotokoll!B6:B33,"PA") -> 0 | E5: =COUNTIF(Prüfprotokoll!F6:F33,TRUE) -> 0 | F5: =COUNTIF(Prüfprotokoll!G6:G33,TRUE) -> 0 | G5: =COUNTIF(Prüfprotokoll!H6:H33,TRUE) -> 0 | H5: =COUNTIF(Prüfprotokoll!I6:I33,"offen") -> 0 | I5: =COUNTIF(Prüfprotokoll!I6:I33,"mehrfach!") -> 0
B6: 3 Überdrückte Zugstraßen | C6: =COUNTIF(Prüfprotokoll!B35:B39,"TIP S2") -> 0 | D6: =COUNTIF(Prüfprotokoll!B35:B39,"PA") -> 0 | E6: =COUNTIF(Prüfprotokoll!F35:F39,TRUE) -> 0 | F6: =COUNTIF(Prüfprotokoll!G35:G39,TRUE) -> 0 | G6: =COUNTIF(Prüfprotokoll!H35:H39,TRUE) -> 0 | H6: =COUNTIF(Prüfprotokoll!I35:I39,"offen") -> 0 | I6: =COUNTIF(Prüfprotokoll!I35:I39,"mehrfach!") -> 0
B7: 4 Rangierstraßen | C7: =COUNTIF(Prüfprotokoll!B41:B61,"TIP S2") -> 0 | D7: =COUNTIF(Prüfprotokoll!B41:B61,"PA") -> 0 | E7: =COUNTIF(Prüfprotokoll!F41:F61,TRUE) -> 0 | F7: =COUNTIF(Prüfprotokoll!G41:G61,TRUE) -> 0 | G7: =COUNTIF(Prüfprotokoll!H41:H61,TRUE) -> 0 | H7: =COUNTIF(Prüfprotokoll!I41:I61,"offen") -> 0 | I7: =COUNTIF(Prüfprotokoll!I41:I61,"mehrfach!") -> 0
B8: 5 Weitere Prüfungen | C8: =COUNTIF(Prüfprotokoll!B63:B90,"TIP S2") -> 0 | D8: =COUNTIF(Prüfprotokoll!B63:B90,"PA") -> 0 | E8: =COUNTIF(Prüfprotokoll!F63:F90,TRUE) -> 0 | F8: =COUNTIF(Prüfprotokoll!G63:G90,TRUE) -> 0 | G8: =COUNTIF(Prüfprotokoll!H63:H90,TRUE) -> 0 | H8: =COUNTIF(Prüfprotokoll!I63:I90,"offen") -> 0 | I8: =COUNTIF(Prüfprotokoll!I63:I90,"mehrfach!") -> 0
B9: Summe | C9: =SUM(C5:C8) -> 0 | D9: =SUM(D5:D8) -> 0 | E9: =SUM(E5:E8) -> 0 | F9: =SUM(F5:F8) -> 0 | G9: =SUM(G5:G8) -> 0 | H9: =SUM(H5:H8) -> 0 | I9: =SUM(I5:I8) -> 0
B11: Davon TIP S2 – n. i. O. | C11: =COUNTIFS(Prüfprotokoll!B5:B90,"TIP S2",Prüfprotokoll!G5:G90,TRUE) -> 0
B12: Davon PA – n. i. O. | C12: =COUNTIFS(Prüfprotokoll!B5:B90,"PA",Prüfprotokoll!G5:G90,TRUE) -> 0
B14: Gesamtergebnis
B15: TIP S2 – Software Fahrstraßenoberfläche – alle Prüfschritte durchgeführt | C15: =IF(AND(H9=0,I9=0),"Ja – alle Fragen beantwortet","Nein – "&H9&" offen, "&I9&" mehrfach angehakt") -> 0
B17: Übertrag der Abweichungen ins Prüfbuch
B18: Kurzbeschreibung | C18: Frage-Nr. | D18: Herkunft | E18: Prüfbuch-Nr. | G18: Element | I18: Erledigt
I19: FALSE
I20: FALSE
I21: FALSE
I22: FALSE
I23: FALSE
I24: FALSE
I25: FALSE
I26: FALSE
I27: FALSE
I28: FALSE
B30: Unterschriften
C31: Prüfer | G31: Freigebender
B32: Name (Druckbuchstaben)
B33: Firma (falls extern)
B34: Datum
B35: Unterschrift
