Workbook

Sheet Deckblatt
B2: Hitachi Rail
B3: Interne Abnahmeprüfung (FFT) · ITC
B5: Prüfprotokoll Bedienoberfläche
B6: TIP S3 – Software Bedienoberfläche und Design Styleguide Lupe/BerÜ
B7: ESTW L90 · Domestic · DB InfraGO
B9: Projektdaten (gelbe Felder ausfüllen)
B10: Projektbezeichnung / PSP
B11: Stellwerk (UZ / ESTW-Z, Ril100)
B12: Bauzustand / AZ-Nr.
B13: LBS-Version
B14: Geprüfte Lupenbilder (Bezeichner)
B15: Geprüfte BerÜ-Bilder (Bezeichner)
... B20: Herkunft der Fragen
B21: TIP S3 | C21: Frage aus dem TIP S3 – Software Bedienoberfläche. Zeile hellorange. Nummer = Fragennummer im TIP S3, Ergebnis 1:1 ins TIP übertragen.
B22: SG | C22: Reine Styleguide-Frage (3JC 1990 25312 ASAFC). Zeile weiß. Die SG-Fragen eines Abschnitts bilden die Antwort auf TIP S3 Nr. 8 (Lupe) bzw. Nr. 10 (BerÜ).
B24: Bewertung
B25: i. O. – in Ordnung | C25: TIP S3: Ja | D25: Darstellung/Funktion entspricht der Vorgabe.
B26: n. i. O. – nicht in Ordnung | C26: TIP S3: Nein | D26: Abweichung im Prüfbuch erfassen, Prüfbuch-Nr. in „Bemerkung“ eintragen.
B27: n. z. – nicht zutreffend | C27: TIP S3: als n. z. kennzeichnen | D27: Sachverhalt kommt im Projekt nicht vor; kurz begründen.
B29: Bedienung der Excel-Datei
B30: • Je Frage genau ein Kästchen anhaken. Die Spalte „Status“ zeigt „offen“, „erledigt“, „n. i. O.“ oder „mehrfach!“ (mehr als ein Haken).
B31: • Spalte „Bezug (Link)“: Klick springt zur zugehörigen Styleguide- bzw. TIP-S3-Frage (↓ = weiter unten, ↑ = weiter oben). Zurück mit Strg + G / F5 oder über den Rücksprung-Link der Zielzeile.
B32: • Über den Filter in Spalte „Herkunft“ lassen sich nur TIP-S3- oder nur SG-Fragen anzeigen.
B33: • TIP-Textfragen (Nr. 36, 44): Ausgabe und Datum der Planbasisliste ins gelbe Feld eintragen.
B34: • Geprüft wird jedes Lupen- und BerÜ-Bild. Eine Frage ist erst „i. O.“, wenn sie für alle Bilder erfüllt ist. Abgestimmte Kundenwünsche: „i. O.“ mit Verweis auf die Abstimmung.
B35: • Die Kästchen sind Excel-Zellkontrollkästchen (Microsoft 365). In älteren Excel-Versionen erscheinen sie als WAHR/FALSCH; dort Wert per Eingabe ändern.

Sheet Prüfprotokoll
A1: Prüfprotokoll Bedienoberfläche – TIP S3 und Design Styleguide
A2: ESTW L90 · DB InfraGO · Prüfgrundlagen: TIP S3 (Template-Ausg. 01), Design Styleguide 3JC 1990 25312 ASAFC Rev. 04 · Projektdaten und Anleitung: Blatt „Deckblatt“
A4: Nr. | B4: Herkunft | C4: TIP-Nr. / SG-Kap. | D4: Prüffrage | E4: Bezug (Link) | F4: i. O. | G4: n. i. O. | H4: n. z. | I4: Status | J4: Bemerkung / Prüfbuch-Nr.
A5: 2 Allgemeine Festlegungen
A6: 1 | B6: SG | C6: 3 | D6: Sind Abweichungen vom Styleguide auf Kundenwunsch (Abnahmeprüfer) mit dem Ril-/LH-Autor abgestimmt und dokumentiert? | F6: FALSE | G6: FALSE | H6: FALSE | I6: =IF(COUNTIF(F6:H6,TRUE)=0,"offen",IF(COUNTIF(F6:H6,TRUE)>1,"mehrfach!",IF(G6=TRUE,"n. i. O.","erledigt"))) -> offen
A7: 2 | B7: SG | C7: 3 | D7: Bestandsanlage: Ist festgelegt, ob der Styleguide in diesem Bauzustand anzuwenden ist (größerer Umbau bzw. Releasewechsel) oder die bisherige Darstellung beibehalten wird? | F7: FALSE | G7: FALSE | H7: FALSE | I7: =IF(COUNTIF(F7:H7,TRUE)=0,"offen",IF(COUNTIF(F7:H7,TRUE)>1,"mehrfach!",IF(G7=TRUE,"n. i. O.","erledigt"))) -> offen
A8: 3 Lupenbilder
A9: TIP S3 – Lupe
A10: 3 | B10: TIP S3 | C10: Nr. 1 | D10: Sind alle Elemente des Stellwerks vorhanden, richtig angeordnet und korrekt bezeichnet? | F10: FALSE | G10: FALSE | H10: FALSE | I10: =IF(COUNTIF(F10:H10,TRUE)=0,"offen",IF(COUNTIF(F10:H10,TRUE)>1,"mehrfach!",IF(G10=TRUE,"n. i. O.","erledigt"))) -> offen
A11: 4 | B11: TIP S3 | C11: Nr. 2 | D11: Sind die Konnektoren fortlaufender Gleise innerhalb des Lupenbildes eindeutig mit Ziffern und zu benachbarten Bildern eindeutig mit großen Buchstaben und dem Bildbezeichner bezeichnet? | F11: FALSE | G11: FALSE | H11: FALSE | I11: =IF(COUNTIF(F11:H11,TRUE)=0,"offen",IF(COUNTIF(F11:H11,TRUE)>1,"mehrfach!",IF(G11=TRUE,"n. i. O.","erledigt"))) -> offen
A12: 5 | B12: TIP S3 | C12: Nr. 3 | D12: Sind alle Isolierstöße korrekt dargestellt? | F12: FALSE | G12: FALSE | H12: FALSE | I12: =IF(COUNTIF(F12:H12,TRUE)=0,"offen",IF(COUNTIF(F12:H12,TRUE)>1,"mehrfach!",IF(G12=TRUE,"n. i. O.","erledigt"))) -> offen
A13: 6 | B13: TIP S3 | C13: Nr. 4 | D13: Ist bei gemeinsam isolierten Weichen die Weiche mit AZG-Befehl mit einem * gekennzeichnet? | F13: FALSE | G13: FALSE | H13: FALSE | I13: =IF(COUNTIF(F13:H13,TRUE)=0,"offen",IF(COUNTIF(F13:H13,TRUE)>1,"mehrfach!",IF(G13=TRUE,"n. i. O.","erledigt"))) -> offen
A14: 7 | B14: TIP S3 | C14: Nr. 5 | D14: Ist bei allen Gleisen ein Verschlussmelder dargestellt? | E14: ↓ SG 3.1.11 | F14: FALSE | G14: FALSE | H14: FALSE | I14: =IF(COUNTIF(F14:H14,TRUE)=0,"offen",IF(COUNTIF(F14:H14,TRUE)>1,"mehrfach!",IF(G14=TRUE,"n. i. O.","erledigt"))) -> offen
A15: 8 | B15: TIP S3 | C15: Nr. 6 | D15: Sind alle notwendigen Bahnhofszeilen dargestellt? | F15: FALSE | G15: FALSE | H15: FALSE | I15: =IF(COUNTIF(F15:H15,TRUE)=0,"offen",IF(COUNTIF(F15:H15,TRUE)>1,"mehrfach!",IF(G15=TRUE,"n. i. O.","erledigt"))) -> offen
A16: 9 | B16: TIP S3 | C16: Nr. 7 | D16: Ist bei Kreuzungsweichen (EKW oder DKW) der Weichenteil mit Merkhinweisen mit * gekennzeichnet? | F16: FALSE | G16: FALSE | H16: FALSE | I16: =IF(COUNTIF(F16:H16,TRUE)=0,"offen",IF(COUNTIF(F16:H16,TRUE)>1,"mehrfach!",IF(G16=TRUE,"n. i. O.","erledigt"))) -> offen
A17: 10 | B17: TIP S3 | C17: Nr. 8 | D17: Entspricht der Aufbau dem Design Style Guide? (Ergebnis aus den SG-Fragen dieses Abschnitts) | E17: ↓ SG 3.1 | F17: FALSE | G17: FALSE | H17: FALSE | I17: =IF(COUNTIF(F17:H17,TRUE)=0,"offen",IF(COUNTIF(F17:H17,TRUE)>1,"mehrfach!",IF(G17=TRUE,"n. i. O.","erledigt"))) -> offen
A18: Styleguide Kap. 3.1 – Lupenbilder
A19: 3.1.1 Bereichsende ESTW-Zentralblock
A20: 11 | B20: SG | C20: 3.1.1 | D20: Sind Start-/Zielpunkte ohne Signal bei zweigleisigen Strecken – soweit möglich – in Fahrtrichtung rechts vom Gleis angeordnet (Ril 819.0603)? | F20: FALSE | G20: FALSE | H20: FALSE | I20: =IF(COUNTIF(F20:H20,TRUE)=0,"offen",IF(COUNTIF(F20:H20,TRUE)>1,"mehrfach!",IF(G20=TRUE,"n. i. O.","erledigt"))) -> offen
A21: 12 | B21: SG | C21: 3.1.1 | D21: Sind kombinierte Blockstart-/Zielpunkte auf der Gleisseite dargestellt, auf der auch die Start-/Zielsignale (ESig/Zbk/LBK/BK) dargestellt sind (LH 415.9212_A1-430)? | F21: FALSE | G21: FALSE | H21: FALSE | I21: =IF(COUNTIF(F21:H21,TRUE)=0,"offen",IF(COUNTIF(F21:H21,TRUE)>1,"mehrfach!",IF(G21=TRUE,"n. i. O.","erledigt"))) -> offen
A22: 13 | B22: SG | C22: 3.1.1 | D22: Ist jeder Blockstartpunkt auf der Gleisseite des zugehörigen Zielsignals und jeder Blockzielpunkt auf der Gleisseite des zugehörigen Startsignals dargestellt, sodass Kreuzbedienungen vermieden werden? | F22: FALSE | G22: FALSE | H22: FALSE | I22: =IF(COUNTIF(F22:H22,TRUE)=0,"offen",IF(COUNTIF(F22:H22,TRUE)>1,"mehrfach!",IF(G22=TRUE,"n. i. O.","erledigt"))) -> offen
A23: 3.1.2 Bereichsende mit Bereichsgrenze vor dem Einfahrsignal
A24: 14 | B24: SG | C24: 3.1.2 | D24: Wird bei einer Bereichsgrenze direkt vor dem Einfahrsignal die Gleisbelegung des letzten Streckengleisabschnitts übertragen und auf der Lupe dargestellt? | F24: FALSE | G24: FALSE | H24: FALSE | I24: =IF(COUNTIF(F24:H24,TRUE)=0,"offen",IF(COUNTIF(F24:H24,TRUE)>1,"mehrfach!",IF(G24=TRUE,"n. i. O.","erledigt"))) -> offen
A25: 15 | B25: SG | C25: 3.1.2 | D25: Hat das Bereichsende den BHA-Befehl (Auflösung bei Störung der Datenverbindung zum Nachbarn), obwohl die Zentralblockfahrstraße zum Bereichsende nicht einstellbar ist? | F25: FALSE | G25: FALSE | H25: FALSE | I25: =IF(COUNTIF(F25:H25,TRUE)=0,"offen",IF(COUNTIF(F25:H25,TRUE)>1,"mehrfach!",IF(G25=TRUE,"n. i. O.","erledigt"))) -> offen
A26: 16 | B26: SG | C26: 3.1.2 | D26: Liegt die Maustrefferfläche für die BHA-Bedienung auf der Bezeichnung des Bereichsendes? | F26: FALSE | G26: FALSE | H26: FALSE | I26: =IF(COUNTIF(F26:H26,TRUE)=0,"offen",IF(COUNTIF(F26:H26,TRUE)>1,"mehrfach!",IF(G26=TRUE,"n. i. O.","erledigt"))) -> offen
A27: 3.1.3 Anordnung von SM-Grenzen im ESTW-Zentralblock
A28: 17 | B28: SG | C28: 3.1.3 | D28: Ist die Bezeichnung von Fahrstraßenzielen analog zu Signalelementen in Fahrtrichtung vor dem Symbol projektiert? | F28: FALSE | G28: FALSE | H28: FALSE | I28: =IF(COUNTIF(F28:H28,TRUE)=0,"offen",IF(COUNTIF(F28:H28,TRUE)>1,"mehrfach!",IF(G28=TRUE,"n. i. O.","erledigt"))) -> offen
A29: 18 | B29: SG | C29: 3.1.3 | D29: Sind Fahrstraßenziele auf der Gleisseite dargestellt, auf der sich auch das Zielsignal befindet (Start-/Zielbedienung auf einer Gleisseite)? | F29: FALSE | G29: FALSE | H29: FALSE | I29: =IF(COUNTIF(F29:H29,TRUE)=0,"offen",IF(COUNTIF(F29:H29,TRUE)>1,"mehrfach!",IF(G29=TRUE,"n. i. O.","erledigt"))) -> offen
A30: 19 | B30: SG | C30: 3.1.3 | D30: Sind nur bedienbare Teilfahrstraßen projektiert – über mindestens einen Gleisabschnitt oder vom Startsignal zu einem virtuellen Zielsignal? | F30: FALSE | G30: FALSE | H30: FALSE | I30: =IF(COUNTIF(F30:H30,TRUE)=0,"offen",IF(COUNTIF(F30:H30,TRUE)>1,"mehrfach!",IF(G30=TRUE,"n. i. O.","erledigt"))) -> offen
A31: 20 | B31: SG | C31: 3.1.3 | D31: Steht ein Hauptsignal direkt an der SM-Grenze: Stellt sich die Teilfahrstraße von der SM-Grenze zum Zielsignal automatisch ein, ohne dass dafür Bedienelemente projektiert sind? | F31: FALSE | G31: FALSE | H31: FALSE | I31: =IF(COUNTIF(F31:H31,TRUE)=0,"offen",IF(COUNTIF(F31:H31,TRUE)>1,"mehrfach!",IF(G31=TRUE,"n. i. O.","erledigt"))) -> offen
A32: 21 | B32: SG | C32: 3.1.3.1 | D32: SM-Grenze vor bzw. hinter einem Hauptsignal: Sind die Fahrstraßen in beiden Richtungen mit den vorgesehenen Start-/Zielbedienungen einstellbar und stellt sich die Blockfahrstraße von der SM-Grenze automatisch ein? | F32: FALSE | G32: FALSE | H32: FALSE | I32: =IF(COUNTIF(F32:H32,TRUE)=0,"offen",IF(COUNTIF(F32:H32,TRUE)>1,"mehrfach!",IF(G32=TRUE,"n. i. O.","erledigt"))) -> offen
A33: 22 | B33: SG | C33: 3.1.3.2 | D33: SM-Grenze vor einem Einfahr- oder Blocksignal, Darstellung auf einem Lupenbild: Entfällt der Elementbezeichner des Bereichsendes direkt vor dem Zielsignal? | F33: FALSE | G33: FALSE | H33: FALSE | I33: =IF(COUNTIF(F33:H33,TRUE)=0,"offen",IF(COUNTIF(F33:H33,TRUE)>1,"mehrfach!",IF(G33=TRUE,"n. i. O.","erledigt"))) -> offen
A34: 23 | B34: SG | C34: 3.1.3.2 | D34: Darstellung auf zwei Lupenbildern: Sind alle Elementbezeichner der Bereichsenden projektiert, und entfällt bei Bezeichnern ohne Bedienhandlung das Symbol (blaues Dreieck)? | F34: FALSE | G34: FALSE | H34: FALSE | I34: =IF(COUNTIF(F34:H34,TRUE)=0,"offen",IF(COUNTIF(F34:H34,TRUE)>1,"mehrfach!",IF(G34=TRUE,"n. i. O.","erledigt"))) -> offen
A35: 24 | B35: SG | C35: 3.1.3.3 | D35: SM-Grenze zwischen zwei Gleisabschnitten ohne Signal: Sind die vorgesehenen Bedienhandlungen möglich, und ist die jeweils erste Zentralblockfahrstraße nicht kommandierbar? | F35: FALSE | G35: FALSE | H35: FALSE | I35: =IF(COUNTIF(F35:H35,TRUE)=0,"offen",IF(COUNTIF(F35:H35,TRUE)>1,"mehrfach!",IF(G35=TRUE,"n. i. O.","erledigt"))) -> offen
A36: 25 | B36: SG | C36: 3.1.3.4 | D36: SM-Grenze zwischen zwei Hauptsignalen (Signale an EAMs unterschiedlicher SMs): Ist die Darstellung ohne Fuß-an-Fuß-Anordnung mit gemeinsamem Fahrwegmelder (FM) korrekt umgesetzt? | F36: FALSE | G36: FALSE | H36: FALSE | I36: =IF(COUNTIF(F36:H36,TRUE)=0,"offen",IF(COUNTIF(F36:H36,TRUE)>1,"mehrfach!",IF(G36=TRUE,"n. i. O.","erledigt"))) -> offen
A37: 3.1.4 Gleise über Lupenbildgrenze
A38: 26 | B38: SG | C38: 3.1.4 | D38: Ist bei zwei- und mehrgleisigen Strecken das in Regelrichtung abgehende Streckengleis der Betriebsstelle zugeordnet und auf deren Lupenbild dargestellt? | E38: ↓ TIP S3 Nr. 20 | F38: FALSE | G38: FALSE | H38: FALSE | I38: =IF(COUNTIF(F38:H38,TRUE)=0,"offen",IF(COUNTIF(F38:H38,TRUE)>1,"mehrfach!",IF(G38=TRUE,"n. i. O.","erledigt"))) -> offen
A39: 27 | B39: SG | C39: 3.1.4 | D39: Ist bei Elementen auf zwei Lupenbildern die Gleisbezeichnung nur auf dem Lupenbild projektiert, von dem aus die Bedienung möglich sein soll (Ril 819.0603)? | F39: FALSE | G39: FALSE | H39: FALSE | I39: =IF(COUNTIF(F39:H39,TRUE)=0,"offen",IF(COUNTIF(F39:H39,TRUE)>1,"mehrfach!",IF(G39=TRUE,"n. i. O.","erledigt"))) -> offen
A40: 28 | B40: SG | C40: 3.1.4 | D40: Ist das GA-Feld (Merkhinweisart, Zugnummer) auf dem Lupenbild mit dem Startsignal der Folgefahrstraße(n) gespiegelt und mit Spiegelfeldbezeichner ohne Gleisbezeichnung dargestellt? | F40: FALSE | G40: FALSE | H40: FALSE | I40: =IF(COUNTIF(F40:H40,TRUE)=0,"offen",IF(COUNTIF(F40:H40,TRUE)>1,"mehrfach!",IF(G40=TRUE,"n. i. O.","erledigt"))) -> offen
A41: 29 | B41: SG | C41: 3.1.4 | D41: Eingleisige Strecke: Ist das Lupenbild für den Elementbezeichner des Streckengleises in Planung/Projektierung festgelegt und die Spiegelung analog umgesetzt? | F41: FALSE | G41: FALSE | H41: FALSE | I41: =IF(COUNTIF(F41:H41,TRUE)=0,"offen",IF(COUNTIF(F41:H41,TRUE)>1,"mehrfach!",IF(G41=TRUE,"n. i. O.","erledigt"))) -> offen
...

Sheet Ergebnis
B2: Ergebnis – Prüfprotokoll Bedienoberfläche
B4: Abschnitt | C4: TIP S3 | D4: SG | E4: i. O. | F4: n. i. O. | G4: n. z. | H4: offen | I4: mehrfach
B5: 2 Allgemeine Festlegungen | C5: =COUNTIF(Prüfprotokoll!B6:B7,"TIP S3") -> 0 | D5: =COUNTIF(Prüfprotokoll!B6:B7,"SG") -> 2 | E5: =COUNTIF(Prüfprotokoll!F6:F7,TRUE) -> 0 | F5: =COUNTIF(Prüfprotokoll!G6:G7,TRUE) -> 0 | G5: =COUNTIF(Prüfprotokoll!H6:H7,TRUE) -> 0 | H5: =COUNTIF(Prüfprotokoll!I6:I7,"offen") -> 2 | I5: =COUNTIF(Prüfprotokoll!I6:I7,"mehrfach!") -> 0
B6: 3 Lupenbilder | C6: =COUNTIF(Prüfprotokoll!B9:B100,"TIP S3") -> 8 | D6: =COUNTIF(Prüfprotokoll!B9:B100,"SG") -> 63 | E6: =COUNTIF(Prüfprotokoll!F9:F100,TRUE) -> 0 | F6: =COUNTIF(Prüfprotokoll!G9:G100,TRUE) -> 0 | G6: =COUNTIF(Prüfprotokoll!H9:H100,TRUE) -> 0 | H6: =COUNTIF(Prüfprotokoll!I9:I100,"offen") -> 71 | I6: =COUNTIF(Prüfprotokoll!I9:I100,"mehrfach!") -> 0
B7: 4 Bereichsübersichtsbilder | C7: =COUNTIF(Prüfprotokoll!B102:B137,"TIP S3") -> 2 | D7: =COUNTIF(Prüfprotokoll!B102:B137,"SG") -> 21 | E7: =COUNTIF(Prüfprotokoll!F102:F137,TRUE) -> 0 | F7: =COUNTIF(Prüfprotokoll!G102:G137,TRUE) -> 0 | G7: =COUNTIF(Prüfprotokoll!H102:H137,TRUE) -> 0 | H7: =COUNTIF(Prüfprotokoll!I102:I137,"offen") -> 23 | I7: =COUNTIF(Prüfprotokoll!I102:I137,"mehrfach!") -> 0
B8: 5 Lupe und BerÜ – allgemeine Prüfungen | C8: =COUNTIF(Prüfprotokoll!B139:B160,"TIP S3") -> 21 | D8: =COUNTIF(Prüfprotokoll!B139:B160,"SG") -> 0 | E8: =COUNTIF(Prüfprotokoll!F139:F160,TRUE) -> 0 | F8: =COUNTIF(Prüfprotokoll!G139:G160,TRUE) -> 0 | G8: =COUNTIF(Prüfprotokoll!H139:H160,TRUE) -> 0 | H8: =COUNTIF(Prüfprotokoll!I139:I160,"offen") -> 21 | I8: =COUNTIF(Prüfprotokoll!I139:I160,"mehrfach!") -> 0
B9: 6 Diagnosemeldungen | C9: =COUNTIF(Prüfprotokoll!B162:B166,"TIP S3") -> 4 | D9: =COUNTIF(Prüfprotokoll!B162:B166,"SG") -> 0 | E9: =COUNTIF(Prüfprotokoll!F162:F166,TRUE) -> 0 | F9: =COUNTIF(Prüfprotokoll!G162:G166,TRUE) -> 0 | G9: =COUNTIF(Prüfprotokoll!H162:H166,TRUE) -> 0 | H9: =COUNTIF(Prüfprotokoll!I162:I166,"offen") -> 4 | I9: =COUNTIF(Prüfprotokoll!I162:I166,"mehrfach!") -> 0
B10: 7 Zugnummernanlage und Zuglenkung | C10: =COUNTIF(Prüfprotokoll!B168:B183,"TIP S3") -> 14 | D10: =COUNTIF(Prüfprotokoll!B168:B183,"SG") -> 0 | E10: =COUNTIF(Prüfprotokoll!F168:F183,TRUE) -> 0 | F10: =COUNTIF(Prüfprotokoll!G168:G183,TRUE) -> 0 | G10: =COUNTIF(Prüfprotokoll!H168:H183,TRUE) -> 0 | H10: =COUNTIF(Prüfprotokoll!I168:I183,"offen") -> 12 | I10: =COUNTIF(Prüfprotokoll!I168:I183,"mehrfach!") -> 0
B11: 8 Projektierungsupdate, Toolprüfung, Migration | C11: =COUNTIF(Prüfprotokoll!B185:B192,"TIP S3") -> 5 | D11: =COUNTIF(Prüfprotokoll!B185:B192,"SG") -> 0 | E11: =COUNTIF(Prüfprotokoll!F185:F192,TRUE) -> 0 | F11: =COUNTIF(Prüfprotokoll!G185:G192,TRUE) -> 0 | G11: =COUNTIF(Prüfprotokoll!H185:H192,TRUE) -> 0 | H11: =COUNTIF(Prüfprotokoll!I185:I192,"offen") -> 5 | I11: =COUNTIF(Prüfprotokoll!I185:I192,"mehrfach!") -> 0
B12: Summe | C12: =SUM(C5:C11) -> 54 | D12: =SUM(D5:D11) -> 86 | E12: =SUM(E5:E11) -> 0 | F12: =SUM(F5:F11) -> 0 | G12: =SUM(G5:G11) -> 0 | H12: =SUM(H5:H11) -> 138 | I12: =SUM(I5:I11) -> 0
B14: Davon TIP S3 – n. i. O. | C14: =COUNTIFS(Prüfprotokoll!B5:B192,"TIP S3",Prüfprotokoll!G5:G192,TRUE) -> 0
B15: Davon SG – n. i. O. | C15: =COUNTIFS(Prüfprotokoll!B5:B192,"SG",Prüfprotokoll!G5:G192,TRUE) -> 0
B17: Gesamtergebnis
B18: TIP S3 – alle Prüfschritte durchgeführt | C18: =IF(AND(H12=0,I12=0),"Ja – alle Fragen beantwortet","Nein – "&H12&" offen, "&I12&" mehrfach angehakt") -> Nein – 138 offen, 0 mehrfach angehakt
B19: Bedienoberfläche entspricht dem Styleguide | C19: =IF(H12+I12>0,"Prüfung noch nicht abgeschlossen",IF(COUNTIFS(Prüfprotokoll!B5:B192,"SG",Prüfprotokoll!G5:G192,TRUE)=0,"Ja","Nein / mit dokumentierten Abweichungen")) -> Prüfung noch nicht abgeschlossen
B21: Übertrag der Abweichungen ins Prüfbuch
B22: Kurzbeschreibung | C22: Frage-Nr. | D22: Herkunft | E22: Prüfbuch-Nr. | G22: Bild (Lupe/BerÜ) | I22: Erledigt
I23: FALSE
I24: FALSE
I25: FALSE
I26: FALSE
I27: FALSE
I28: FALSE
I29: FALSE
I30: FALSE
I31: FALSE
I32: FALSE
B34: Unterschriften
C35: Prüfer | G35: Freigebender
B36: Name (Druckbuchstaben)
B37: Firma (falls extern)
B38: Datum
B39: Unterschrift
